Workbook

Sheet logistica_participants
R1: limit | S1: 50 | T1: km | U1: limit | W1: km
A2: Categoria | B2: Companyia | C2: Nom | D2: DNI | E2: Email | F2: Telèfon | G2: Municipi | H2: Distància (km) | I2: Ruta Google Maps | S2: km a pagar | T2: eur a pagar | V2: km a pagar | W2: eur a pagar
A3: Arts Vives | B3: Els Braves | C3: Aleix | D3: 41645308J | E3: agazquezverdaguer@gmail.com | F3: 675809849 | G3: Quart | H3: 22.4 | I3: https://www.google.com/maps/dir/?api=1&origin=Sant+Jordi+Desvalls&destination=Quart | S3: =+IF(H3>Full1!S$1,H3-Full1!S$1,0)*2 -> 44.8 | T3: =+S3*0.25 -> 11.2 | V3: =+IF(H3>Full1!V$1,H3-Full1!V$1,0)*2 -> 44.8 | W3: =+V3*0.25 -> 11.2
A4: Arts Vives | B4: Pamboliteatre | C4: QUIM CASTELLA TURON | D4: 387850067Z | E4: pamboliteatre@gmail.com | F4: 669203640 | G4: MATARO | H4: 87.4 | I4: https://www.google.com/maps/dir/?api=1&origin=Sant+Jordi+Desvalls&destination=MATARO | S4: =+IF(H4>Full1!S$1,H4-Full1!S$1,0)*2 -> 174.8 | T4: =+S4*0.25 -> 43.7 | V4: =+IF(H4>Full1!V$1,H4-Full1!V$1,0)*2 -> 174.8 | W4: =+V4*0.25 -> 43.7
A5: Arts Vives | B5: Djammal | C5: Jose Miguel Martins Semedo | D5: X8561939M | E5: clownonpopping@gmail.com | F5: 600031910 | G5: La Bisbal d'Empordà | H5: 16.6 | I5: https://www.google.com/maps/dir/?api=1&origin=Sant+Jordi+Desvalls&destination=La%20Bisbal%20d%27Empord%C3%A0 | S5: =+IF(H5>Full1!S$1,H5-Full1!S$1,0)*2 -> 33.2 | T5: =+S5*0.25 -> 8.3 | V5: =+IF(H5>Full1!V$1,H5-Full1!V$1,0)*2 -> 33.2 | W5: =+V5*0.25 -> 8.3
A6: Arts Vives | B6: Barret's Garden | C6: Santi Cos Giner | D6: 38846985A | E6: barretsgarden@gmail.com | F6: 656335924 | G6: Cervià de Ter | H6: 3.8 | I6: https://www.google.com/maps/dir/?api=1&origin=Sant+Jordi+Desvalls&destination=Cervi%C3%A0%20de%20Ter | S6: =+IF(H6>Full1!S$1,H6-Full1!S$1,0)*2 -> 7.6 | T6: =+S6*0.25 -> 1.9 | V6: =+IF(H6>Full1!V$1,H6-Full1!V$1,0)*2 -> 7.6 | W6: =+V6*0.25 -> 1.9
A7: Arts Vives | B7: Duo Belarc | C7: Laura Almiñana | D7: 21774253S | E7: duobelarc@gmail.com | F7: 640350763 | G7: Barcelona | H7: 119.7 | I7: https://www.google.com/maps/dir/?api=1&origin=Sant+Jordi+Desvalls&destination=Barcelona | S7: =+IF(H7>Full1!S$1,H7-Full1!S$1,0)*2 -> 239.4 | T7: =+S7*0.25 -> 59.85 | V7: =+IF(H7>Full1!V$1,H7-Full1!V$1,0)*2 -> 239.4 | W7: =+V7*0.25 -> 59.85
A8: Arts Vives | B8: Rumbesia | C8: Jose Manuel Panzano Sancho | D8: 46624948s | E8: jose.panzano@gmail.com | F8: 660656698 | G8: Sant Cugat del Vallès | H8: 113.2 | I8: https://www.google.com/maps/dir/?api=1&origin=Sant+Jordi+Desvalls&destination=Sant%20Cugat%20del%20Vall%C3%A8s | S8: =+IF(H8>Full1!S$1,H8-Full1!S$1,0)*2 -> 226.4 | T8: =+S8*0.25 -> 56.6 | V8: =+IF(H8>Full1!V$1,H8-Full1!V$1,0)*2 -> 226.4 | W8: =+V8*0.25 -> 56.6
A9: Arts Vives | B9: OMMATIDIA | C9: Laura Netz | D9: 46973248a | E9: laura@netzzz.net | F9: 662093243 | G9: Colera | H9: 54.8 | I9: https://www.google.com/maps/dir/?api=1&origin=Sant+Jordi+Desvalls&destination=Colera | S9: =+IF(H9>Full1!S$1,H9-Full1!S$1,0)*2 -> 109.6 | T9: =+S9*0.25 -> 27.4 | V9: =+IF(H9>Full1!V$1,H9-Full1!V$1,0)*2 -> 109.6 | W9: =+V9*0.25 -> 27.4
A10: Arts Vives | B10: La Pulposa | C10: Gaia Magrané | D10: 41562548F | E10: ambar.gmg.gmg@gmail.com | F10: 638024551 | G10: Sant Jordi Desvalls | H10: 0 | I10: https://www.google.com/maps/dir/?api=1&origin=Sant+Jordi+Desvalls&destination=Sant%20Jordi%20Desvalls | S10: =+IF(H10>Full1!S$1,H10-Full1!S$1,0)*2 -> 0 | T10: =+S10*0.25 -> 0 | V10: =+IF(H10>Full1!V$1,H10-Full1!V$1,0)*2 -> 0 | W10: =+V10*0.25 -> 0
A11: Arts Vives | B11: TRES PELS PÈLS TEATRE | C11: LAURA CATALAN GARCIA | D11: 77990396H | E11: trespelspels@gmail.com | F11: 635545306 | G11: GIRONA | H11: 21.9 | I11: https://www.google.com/maps/dir/?api=1&origin=Sant+Jordi+Desvalls&destination=GIRONA | S11: =+IF(H11>Full1!S$1,H11-Full1!S$1,0)*2 -> 43.8 | T11: =+S11*0.25 -> 10.95 | V11: =+IF(H11>Full1!V$1,H11-Full1!V$1,0)*2 -> 43.8 | W11: =+V11*0.25 -> 10.95
A12: Arts Vives | B12: Pau Zabala Padró | C12: Pau | D12: 77919808V | E12: pauzabala_4@hotmail.com | F12: 606865341 | G12: Figueres | H12: 28.5 | I12: https://www.google.com/maps/dir/?api=1&origin=Sant+Jordi+Desvalls&destination=Figueres | S12: =+IF(H12>Full1!S$1,H12-Full1!S$1,0)*2 -> 57 | T12: =+S12*0.25 -> 14.25 | V12: =+IF(H12>Full1!V$1,H12-Full1!V$1,0)*2 -> 57 | W12: =+V12*0.25 -> 14.25
A13: Arts Vives | B13: Terapia de riure | C13: oriol serra pages | D13: 41579652E | E13: oriolserrapages@gmail.com | F13: 972798135 | G13: SANT JORDI DESVALLS | H13: 0 | I13: https://www.google.com/maps/dir/?api=1&origin=Sant+Jordi+Desvalls&destination=SANT%20JORDI%20DESVALLS | S13: =+IF(H13>Full1!S$1,H13-Full1!S$1,0)*2 -> 0 | T13: =+S13*0.25 -> 0 | V13: =+IF(H13>Full1!V$1,H13-Full1!V$1,0)*2 -> 0 | W13: =+V13*0.25 -> 0
A14: Arts Vives | B14: cia. cabra cadabra | C14: Hélène Hüsler | D14: Y9206219T | E14: cia.cabracadabra@gmail.com | F14: 653606309 | G14: Barcelona | H14: 119.7 | I14: https://www.google.com/maps/dir/?api=1&origin=Sant+Jordi+Desvalls&destination=Barcelona | S14: =+IF(H14>Full1!S$1,H14-Full1!S$1,0)*2 -> 239.4 | T14: =+S14*0.25 -> 59.85 | V14: =+IF(H14>Full1!V$1,H14-Full1!V$1,0)*2 -> 239.4 | W14: =+V14*0.25 -> 59.85
A15: Arts Vives | B15: Lia i Marga | S15: =+IF(H15>Full1!S$1,H15-Full1!S$1,0)*2 -> 0 | T15: =+S15*0.25 -> 0 | V15: =+IF(H15>Full1!V$1,H15-Full1!V$1,0)*2 -> 0 | W15: =+V15*0.25 -> 0
A16: Arts Vives | B16: Albert i Helena | G16: Barcelona | H16: 119.7 | I16: https://www.google.com/maps/dir/?api=1&origin=Sant+Jordi+Desvalls&destination=Barcelona | S16: =+IF(H16>Full1!S$1,H16-Full1!S$1,0)*2 -> 239.4 | T16: =+S16*0.25 -> 59.85 | V16: =+IF(H16>Full1!V$1,H16-Full1!V$1,0)*2 -> 239.4 | W16: =+V16*0.25 -> 59.85
A17: Arts Vives | B17: DJ PIPA | S17: =+IF(H17>Full1!S$1,H17-Full1!S$1,0)*2 -> 0 | T17: =+S17*0.25 -> 0 | V17: =+IF(H17>Full1!V$1,H17-Full1!V$1,0)*2 -> 0 | W17: =+V17*0.25 -> 0
C18: Dolores Duran | D18: 40280368p | E18: dduranarcas@gmail.com | F18: 635414083 | G18: Girona capital | H18: 21.9 | I18: https://www.google.com/maps/dir/?api=1&origin=Sant+Jordi+Desvalls&destination=Girona | S18: =+IF(H18>S$1,H18-S$1,0)*2 -> 0 | T18: =+S18*0.25 -> 0 | V18: =+IF(H18>V$1,H18-V$1,0)*2 -> 43.8 | W18: =+V18*0.25 -> 10.95
C19: Lourdes Doñate | E19: lourdesdb73@gmail.com | F19: TELF DEL CESC -630920519 | G19: Carrer Escoles 16, Sant Martí de Tous 08712 | S19: =+IF(H19>S$1,H19-S$1,0)*2 -> 0 | T19: =+S19*0.25 -> 0 | V19: =+IF(H19>V$1,H19-V$1,0)*2 -> 0 | W19: =+V19*0.25 -> 0
C20: Cesc Oliveras. | D20: 35119814X | E20: foorfebre@gmail.com | F20: 630920517 | G20: El Bruc | H20: 142.1 | I20: https://www.google.com/maps/dir/?api=1&origin=Sant+Jordi+Desvalls&destination=El%20Bruc | S20: =+IF(H20>S$1,H20-S$1,0)*2 -> 184.2 | T20: =+S20*0.25 -> 46.05 | V20: =+IF(H20>V$1,H20-V$1,0)*2 -> 284.2 | W20: =+V20*0.25 -> 71.05
C21: Àngel Martinez | D21: 79280026S | E21: angel@angelmartinez.cat | F21: 626032030 | G21: Subirats | H21: 147.1 | I21: https://www.google.com/maps/dir/?api=1&origin=Sant+Jordi+Desvalls&destination=Subirats | S21: =+IF(H21>S$1,H21-S$1,0)*2 -> 194.2 | T21: =+S21*0.25 -> 48.55 | V21: =+IF(H21>V$1,H21-V$1,0)*2 -> 294.2 | W21: =+V21*0.25 -> 73.55
C22: Antonio Majuelos | D22: 36935877Q | E22: amajols@gmail.com | F22: 609038033 | G22: Girona | H22: 21.9 | I22: https://www.google.com/maps/dir/?api=1&origin=Sant+Jordi+Desvalls&destination=Girona | S22: =+IF(H22>S$1,H22-S$1,0)*2 -> 0 | T22: =+S22*0.25 -> 0 | V22: =+IF(H22>V$1,H22-V$1,0)*2 -> 43.8 | W22: =+V22*0.25 -> 10.95
C23: Conrad | G23: Sant Jordi Desvalls | H23: 0 | S23: =+IF(H23>S$1,H23-S$1,0)*2 -> 0 | T23: =+S23*0.25 -> 0 | V23: =+IF(H23>V$1,H23-V$1,0)*2 -> 0 | W23: =+V23*0.25 -> 0
C24: Emili Biarnès | G24: Cervià de Ter | H24: 4 | I24: https://www.google.com/maps/dir/Carrer+del+Doctor+Joher,+15,+17464+Sant+Jordi+Desvalls,+Girona,+Espanya/Cervi%C3%A0+de+Ter,+17464,+Girona/@42.0685496,2.9216658,3227m/data=!3m2!1e3!4b1!4m14!4m13!1m5!1m1!1s0x12baf039b9d4a5ad:0x48b79493cf6710a2!2m2!1d2.9544194!2d42.068553!1m5!1m1!1s0x12baefbb76eca33d:0xde1eed8a3c9a6685!2m2!1d2.9094816!2d42.0667654!3e0?entry=ttu&g_ep=EgoyMDI2MDgwOS4wIKXMDSoASAFQAw%3D%3D | S24: =+IF(H24>S$1,H24-S$1,0)*2 -> 0 | T24: =+S24*0.25 -> 0 | V24: =+IF(H24>V$1,H24-V$1,0)*2 -> 8 | W24: =+V24*0.25 -> 2
C25: Teresa Ferro | D25: 36898808T | E25: tresfarro@hotmail.com | F25: 669141656 | G25: Sant Just Desvern | H25: 128.4 | I25: https://www.google.com/maps/dir/?api=1&origin=Sant+Jordi+Desvalls&destination=Sant%20Just%20Desvern | S25: =+IF(H25>S$1,H25-S$1,0)*2 -> 156.8 | T25: =+S25*0.25 -> 39.2 | V25: =+IF(H25>V$1,H25-V$1,0)*2 -> 256.8 | W25: =+V25*0.25 -> 64.2
C26: Angela Batlle | G26: Sant Jordi Desvalls | H26: 0 | S26: =+IF(H26>S$1,H26-S$1,0)*2 -> 0 | T26: =+S26*0.25 -> 0 | V26: =+IF(H26>V$1,H26-V$1,0)*2 -> 0 | W26: =+V26*0.25 -> 0
C27: Daniel Ministral | G27: Sant Jordi Desvalls | H27: 0 | S27: =+IF(H27>S$1,H27-S$1,0)*2 -> 0 | T27: =+S27*0.25 -> 0 | V27: =+IF(H27>V$1,H27-V$1,0)*2 -> 0 | W27: =+V27*0.25 -> 0
C28: Paz Muntades | D28: 45883197Z | E28: muntadaaspaz@gmail.com | F28: 645290106 | G28: Salt | H28: 25.1 | I28: https://www.google.com/maps/dir/?api=1&origin=Sant+Jordi+Desvalls&destination=Salt | S28: =+IF(H28>S$1,H28-S$1,0)*2 -> 0 | T28: =+S28*0.25 -> 0 | V28: =+IF(H28>V$1,H28-V$1,0)*2 -> 50.2 | W28: =+V28*0.25 -> 12.55
C29: Majo Menendez | D29: X4590489B | E29: majomenendez.art@gmail.com | F29: 675275868 | G29: Salt | H29: 25.1 | I29: https://www.google.com/maps/dir/?api=1&origin=Sant+Jordi+Desvalls&destination=Salt | S29: =+IF(H29>S$1,H29-S$1,0)*2 -> 0 | T29: =+S29*0.25 -> 0 | V29: =+IF(H29>V$1,H29-V$1,0)*2 -> 50.2 | W29: =+V29*0.25 -> 12.55
C30: Emilia Serradell | D30: 38110229B | E30: eliserradell@hotmail.com | F30: 658821488 | G30: BADALONA | H30: 116 | I30: https://www.google.com/maps/dir/Carrer+del+Doctor+Joher,+15,+17464+Sant+Jordi+Desvalls,+Girona,+Espanya/Badalona,+Barcelona/@41.7473593,2.2361582,103790m/data=!3m2!1e3!4b1!4m14!4m13!1m5!1m1!1s0x12baf039b9d4a5ad:0x48b79493cf6710a2!2m2!1d2.9544194!2d42.068553!1m5!1m1!1s0x12a4bb1298efb741:0x987b0abc3e6ea84d!2m2!1d2.2456681!2d41.4493052!3e0?entry=ttu&g_ep=EgoyMDI2MDgwOS4wIKXMDSoASAFQAw%3D%3D | S30: =+IF(H30>S$1,H30-S$1,0)*2 -> 132 | T30: =+S30*0.25 -> 33 | V30: =+IF(H30>V$1,H30-V$1,0)*2 -> 232 | W30: =+V30*0.25 -> 58
C31: Escola de Celrà. | G31: Celrà | H31: 14.8 | I31: https://www.google.com/maps/dir/Carrer+del+Doctor+Joher,+15,+17464+Sant+Jordi+Desvalls,+Girona,+Espanya/Celr%C3%A0,+17460,+Girona/@42.0459051,2.8639467,12913m/data=!3m2!1e3!4b1!4m14!4m13!1m5!1m1!1s0x12baf039b9d4a5ad:0x48b79493cf6710a2!2m2!1d2.9544194!2d42.068553!1m5!1m1!1s0x12bae5939ef92a9d:0x953ccabfb5d6ba90!2m2!1d2.8764481!2d42.0282649!3e0?entry=ttu&g_ep=EgoyMDI2MDgwOS4wIKXMDSoASAFQAw%3D%3D | S31: =+IF(H31>S$1,H31-S$1,0)*2 -> 0 | T31: =+S31*0.25 -> 0 | V31: =+IF(H31>V$1,H31-V$1,0)*2 -> 29.6 | W31: =+V31*0.25 -> 7.4
C32: Cristina Perez | D32: 45462779j | E32: cristinaperezalay@gmail.com | F32: 649165093 | G32: FONTS, LES (TERRASSA) | H32: 120 | I32: https://www.google.com/maps/place/Les+Fonts,+Barcelona/@41.5264038,2.0276974,1627m/data=!3m2!1e3!4b1!4m6!3m5!1s0x12a493b5d6696e63:0x7d322b6f1de8cac4!8m2!3d41.5270948!4d2.0334418!16s%2Fm%2F0wr971n?entry=ttu&g_ep=EgoyMDI2MDgwOS4wIKXMDSoASAFQAw%3D%3D | S32: =+IF(H32>S$1,H32-S$1,0)*2 -> 140 | T32: =+S32*0.25 -> 35 | V32: =+IF(H32>V$1,H32-V$1,0)*2 -> 240 | W32: =+V32*0.25 -> 60
C33: Rosa Aguilò. | D33: 40516907S | E33: rosaaguilo5@gmail.com | F33: 652535447 | G33: 17200 Palafrugell | H33: 27.8 | I33: https://www.google.com/maps/dir/Carrer+del+Doctor+Joher,+15,+17464+Sant+Jordi+Desvalls,+Girona,+Espanya/Palafrugell,+17200,+Girona/@42.0018977,2.9752539,25844m/data=!3m2!1e3!4b1!4m14!4m13!1m5!1m1!1s0x12baf039b9d4a5ad:0x48b79493cf6710a2!2m2!1d2.9544194!2d42.068553!1m5!1m1!1s0x12ba5461952cfa7f:0x1e4e67cece32a232!2m2!1d3.1624042!2d41.918304!3e0?entry=ttu&g_ep=EgoyMDI2MDgwOS4wIKXMDSoASAFQAw%3D%3D | S33: =+IF(H33>S$1,H33-S$1,0)*2 -> 0 | T33: =+S33*0.25 -> 0 | V33: =+IF(H33>V$1,H33-V$1,0)*2 -> 55.6 | W33: =+V33*0.25 -> 13.9
C34: Montse Planas. | G34: Girona | H34: 21.9 | I34: https://www.google.com/maps/dir/?api=1&origin=Sant+Jordi+Desvalls&destination=Girona | S34: =+IF(H34>S$1,H34-S$1,0)*2 -> 0 | T34: =+S34*0.25 -> 0 | V34: =+IF(H34>V$1,H34-V$1,0)*2 -> 43.8 | W34: =+V34*0.25 -> 10.95
R35: total km | S35: =+SUM(S3:S34) -> 2222.6 | T35: =+SUM(T3:T34) -> 555.65 | V35: =+SUM(V3:V34) -> 3047.6 | W35: =+SUM(W3:W34) -> 761.9
R36: total euros | S36: =+S35*0.25 -> 555.65 | V36: =+V35*0.25 -> 761.9
A38: Arts Plàstiques | C38: Majo Menéndez | D38: X4590489B | E38: majomenendez.art@gmail.com | F38: 675275868 | G38: Salt | H38: 25.1 | I38: https://www.google.com/maps/dir/?api=1&origin=Sant+Jordi+Desvalls&destination=Salt | S38: =+IF(H38>S$1,H38-S$1,0)*2 -> 0 | T38: =+S38*0.25 -> 0 | V38: =+IF(H38>V$1,H38-V$1,0)*2 -> 50.2 | W38: =+V38*0.25 -> 12.55
A39: Arts Plàstiques | C39: Dolores Durán | D39: 40280368p | E39: dduranarcas@gmail.com | F39: 635414083 | G39: Girona capital | H39: 21.9 | I39: https://www.google.com/maps/dir/?api=1&origin=Sant+Jordi+Desvalls&destination=Girona | S39: =+IF(H39>S$1,H39-S$1,0)*2 -> 0 | T39: =+S39*0.25 -> 0 | V39: =+IF(H39>V$1,H39-V$1,0)*2 -> 43.8 | W39: =+V39*0.25 -> 10.95
A40: Arts Plàstiques | C40: Àngel Martínez | D40: 79280026S | E40: angel@angelmartinez.cat | F40: 626032030 | G40: Subirats | H40: 147.1 | I40: https://www.google.com/maps/dir/?api=1&origin=Sant+Jordi+Desvalls&destination=Subirats | S40: =+IF(H40>S$1,H40-S$1,0)*2 -> 194.2 | T40: =+S40*0.25 -> 48.55 | V40: =+IF(H40>V$1,H40-V$1,0)*2 -> 294.2 | W40: =+V40*0.25 -> 73.55
A41: Arts Plàstiques | C41: Rosa Aguiló | D41: 40516907S | E41: rosaaguilo5@gmail.com | F41: 652535447 | G41: Palafrugell | H41: 34.2 | I41: https://www.google.com/maps/dir/?api=1&origin=Sant+Jordi+Desvalls&destination=Palafrugell | S41: =+IF(H41>S$1,H41-S$1,0)*2 -> 0 | T41: =+S41*0.25 -> 0 | V41: =+IF(H41>V$1,H41-V$1,0)*2 -> 68.4 | W41: =+V41*0.25 -> 17.1
...

Sheet Full1
B1: Dolores Durán | C1: Dolores Durán
B2: Àngel Martínez | C2: idem
B3: Rosa Aguiló | C3: Rosa Aguiló
B4: Porcellana Olga Miró | C4: Olga Miró
B5: Antonio Majuelos | C5: Antonio Majuelos
B6: Cesc Oliveras | C6: Francesc Oliveras i Ballús
B8: ARAL | C8: LARA GOMBAU CANO
B9: cristina Perez | C9: cristina Perez
B10: Majo Menéndez | C10: Majo Menéndez
B11: Paz Muntadas | C11: Paz Muntadas
B12: ESCOLA DE DIBUIX I PINTURA DE CELRA | C12: Consol Riera
B13: M TERESSA FERRO LEON | C13: Consol Riera Aranda
... B30: cia. cabra cadabra | C30: Hélène Hüsler
A48: Arts Vives | B48: El Viatge de les Remeires | C48: Pilar | D48: 38101606j | E48: itakaalquimiaherbal@gmail.com | F48: 633196567 | G48: Calonge i Sant antoni | H48: 41.2 | I48: https://www.google.com/maps/dir/?api=1&origin=Sant+Jordi+Desvalls&destination=Calonge%20i%20Sant%20antoni | S48: =+IF(H48>S$1,H48-S$1,0)*2 -> 82.4 | T48: =+S48*0.25 -> 20.6 | V48: =+IF(H48>V$1,H48-V$1,0)*2 -> 82.4 | W48: =+V48*0.25 -> 20.6
A49: Arts Vives | B49: KA TEATRE | C49: Montse | D49: G01852649 | E49: kateatre@gmail.com | F49: 617084848 | G49: Vilanova del Camí | H49: 159.6 | I49: https://www.google.com/maps/dir/?api=1&origin=Sant+Jordi+Desvalls&destination=Vilanova%20del%20Cam%C3%AD | S49: =+IF(H49>S$1,H49-S$1,0)*2 -> 319.2 | T49: =+S49*0.25 -> 79.8 | V49: =+IF(H49>V$1,H49-V$1,0)*2 -> 319.2 | W49: =+V49*0.25 -> 79.8
A50: Arts Vives | B50: Martademarte & Cia | C50: Marta Ribas | D50: 43674067B | E50: martademarte@martademarte.com | F50: 630626707 | G50: Blanes -Girona | H50: 60.1 | I50: https://www.google.com/maps/dir/?api=1&origin=Sant+Jordi+Desvalls&destination=Blanes%20-Girona | S50: =+IF(H50>S$1,H50-S$1,0)*2 -> 120.2 | T50: =+S50*0.25 -> 30.05 | V50: =+IF(H50>V$1,H50-V$1,0)*2 -> 120.2 | W50: =+V50*0.25 -> 30.05
A51: Arts Vives | B51: ARAL | C51: LARA GOMBAU CANO | D51: 47827514A | E51: laragombau@gmail.com | F51: 600035355 | G51: BARCELONA | H51: 119.7 | I51: https://www.google.com/maps/dir/?api=1&origin=Sant+Jordi+Desvalls&destination=BARCELONA | S51: =+IF(H51>S$1,H51-S$1,0)*2 -> 239.4 | T51: =+S51*0.25 -> 59.85 | V51: =+IF(H51>V$1,H51-V$1,0)*2 -> 239.4 | W51: =+V51*0.25 -> 59.85
A52: Arts Vives | B52: cristina Perez | C52: cristina Perez | D52: 45462779j | E52: CRISTINAPEREZALAY@GMAIL.COM | F52: 649165093 | G52: Terrassa | H52: 126.8 | I52: https://www.google.com/maps/dir/?api=1&origin=Sant+Jordi+Desvalls&destination=Terrassa | S52: =+IF(H52>S$1,H52-S$1,0)*2 -> 253.6 | T52: =+S52*0.25 -> 63.4 | V52: =+IF(H52>V$1,H52-V$1,0)*2 -> 253.6 | W52: =+V52*0.25 -> 63.4
A53: Arts Vives | B53: La Pròxima | C53: Júlia | D53: 77633127P | E53: juliapbiel@gmail.com | F53: 662425617 | G53: Cervià de ter | H53: 3.8 | I53: https://www.google.com/maps/dir/?api=1&origin=Sant+Jordi+Desvalls&destination=Cervi%C3%A0%20de%20ter | S53: =+IF(H53>S$1,H53-S$1,0)*2 -> 7.6 | T53: =+S53*0.25 -> 1.9 | V53: =+IF(H53>V$1,H53-V$1,0)*2 -> 7.6 | W53: =+V53*0.25 -> 1.9
